Workbook

Sheet 4月考勤汇总
A1: 4月份共30天，默认应出勤25.00天。实际出勤由考勤策略、有效打卡和人工调整共同计算；请以核算明细为准。
A2: 西鸣科技-2026年4月份考勤汇总表
A3: 序号 | B3: 部门 | C3: 岗位 | D3: 姓名 | E3: 入职日期 | F3: 状态 | G3: 应出勤天数 | H3: 休假天数 | I3: 请假天数 | J3: 加班时长 （单位：天） | K3: 实际出勤天数 | L3: 考勤【主管核对】 | P3: 手机号码 | Q3: 银行卡信息 | W3: 核算备注
L4: 迟到/次 | M4: 旷工/次 | N4: 缺卡/次 | O4: 扣款 | Q4: 银行名称 | R4: 开户人 | S4: 开户省份 | T4: 开户行 | U4: 银行卡号 | V4: 支付宝账号
A5: 1 | B5: 人事行政中心 | C5: 保洁（兼职） | D5: 陈臣 | E5: 45705 | F5: 已转正 | G5: 25 | H5: =30-G5 | K5: ='核算明细'!J2 | P5: 18967470231 | Q5: 中国银行 | R5: 陈臣 | S5: 浙江省 | T5: 后宅支行 | U5: 621 7856 2000 6872 4744 | V5: 18967470231
A6: 2 | B6: 人事行政中心 | C6: 人事部负责人 | D6: 方新阳 | E6: 45848 | F6: 已转正 | G6: 25 | H6: =30-G6 | K6: ='核算明细'!J3 | P6: 13735612125 | Q6: 农业银行 | R6: 方新阳 | S6: 浙江省 | T6: 义乌农业银行农贸城支行 | U6: 6228430386901542773 | V6: 984243694@qq.com
A7: 3 | B7: 人事行政中心 | C7: 人事专员 | D7: 白雪 | E7: 45967 | F7: 已转正 | G7: 25 | H7: =30-G7 | K7: ='核算明细'!J4 | P7: 17357969910 | Q7: 工商银行 | R7: 白雪 | S7: 西藏自治区分行营业部 | T7: 拉萨市城关区金珠西路107号圣城锦苑商业综合楼A座 | U7: 6215580158001404138 | V7: 17357969910
A8: 4 | B8: 人事行政中心 | C8: 人事专员 | D8: 俞美燕 | E8: 46080 | F8: 已转正 | G8: 25 | H8: =30-G8 | K8: ='核算明细'!J5 | P8: 15807935967 | Q8: 招商银行 | R8: 俞美燕 | S8: 浙江省 | T8: 杭州湖墅支行 | U8: 6214836147154773 | V8: 15807935967
A9: 5 | B9: 仓储部 | C9: 仓储员 | D9: 杨国芳 | E9: 44256 | F9: 已转正 | G9: 25 | H9: =30-G9 | K9: ='核算明细'!J6 | P9: 18738766853 | Q9: 农业银行 | R9: 杨国芳 | S9: 河南省 | T9: 唐河县桐寨铺支行 | U9: 6228 4809 7952 2034 672 | V9: 无
A10: 6 | B10: 仓储部 | C10: 仓储员 | D10: 李红中 | E10: 43556 | F10: 已转正 | G10: 25 | H10: =30-G10 | K10: ='核算明细'!J7 | P10: 18903773861 | Q10: 工商银行 | R10: 李红中 | S10: 河南省 | T10: / | U10: 6212 2612 0801 5948 910 | V10: 无
A11: 7 | B11: 仓储部 | C11: 仓储负责人 | D11: 李选 | E11: 43647 | F11: 已转正 | G11: 25 | H11: =30-G11 | K11: ='核算明细'!J8 | P11: 18336649723 | Q11: 工商银行 | R11: 李选 | S11: 河南省 | T11: 中国工商银行河南省郑州市郑州玫瑰城支行 | U11: 6212 2617 0203 9266 176 | V11: 18336649723
A12: 8 | B12: 天猫 | C12: 平台系负责人 | D12: 王娅玲 | E12: 43024 | F12: 已转正 | G12: 25 | H12: =30-G12 | K12: ='核算明细'!J9 | P12: 15738855022 | Q12: 中国银行 | R12: 王娅玲 | S12: 河南省 | T12: 中国银行新郑人民路支行 | U12: 6217 9080 0000 0737 285 | V12: 15738855022
A13: 9 | B13: 天猫 | C13: 运营专员 | D13: 蔡玉婷 | E13: 45117 | F13: 已转正 | G13: 25 | H13: =30-G13 | K13: ='核算明细'!J10 | P13: 13766425819 | Q13: 工商银行 | R13: 蔡玉婷 | S13: 江西省 | T13: 江西宜春丰城新城支行 | U13: 6215 5815 5080 0554 5626 | V13: 13766425819
A14: 10 | B14: 天猫 | C14: 平台系天猫负责人 | D14: 韩云峰 | E14: 42430 | F14: 已转正 | G14: 25 | H14: =30-G14 | K14: ='核算明细'!J11 | P14: 13065991203 | Q14: 农业银行 | R14: 韩云峰 | S14: 浙江省 | T14: 农行义乌向阳支行 | U14: 6228 4303 8969 2878 372 | V14: 1821353677@qq.com
A15: 11 | B15: 天猫 | C15: 运营专员 | D15: 邓帅齐 | E15: 45747 | F15: 已转正 | G15: 25 | H15: =30-G15 | K15: ='核算明细'!J12 | P15: 15970386247 | Q15: 建设银行 | R15: 邓齐帅 | S15: 江西省 | T15: 横峰支行 | U15: 6217002089985357891 | V15: 15970386247
A16: 12 | B16: 天猫 | C16: 运营助理 | D16: 周文博 | E16: 45778 | F16: 试用期 | G16: 25 | H16: =30-G16 | K16: ='核算明细'!J13 | P16: 18613741185 | Q16: 中国银行 | R16: 周文博 | S16: 河南省 | T16: 中国银行固始聊城大道支行 | U16: 6217858000127452065 | V16: 18613741185
... A35: 31 | B35: 总经办 | C35: 总经理助理 | D35: 王一航 | E35: 44970 | F35: 已转正 | G35: 25 | H35: =30-G35 | K35: ='核算明细'!J32 | P35: 17888295389 | Q35: 招商银行 | R35: 王一航 | S35: 浙江省 | T35: 义乌支行 | U35: 6214835795709037 | V35: 17888295389
A36: 32 | B36: 总经办 | C36: 董事长 | D36: 沈靖富 | F36: 创始人 | G36: 25 | H36: =30-G36 | K36: ='核算明细'!J33 | P36: 18157917550 | R36: 沈靖富 | S36: 浙江省 | T36: 兴业银行义乌城中支行 | U36: 622908353248265818
A37: 33 | B37: 总经办 | C37: 总经理 | D37: 骆军阳 | E37: 44075 | F37: 已转正 | G37: 25 | H37: =30-G37 | K37: ='核算明细'!J34 | P37: 13676816332 | Q37: 农业银行 | R37: 骆军阳 | S37: 浙江省 | T37: 义乌义亭支行 | U37: 6228 4803 8847 6733 372 | V37: jerney520@163.com
A38: 34 | B38: 抖音组 | C38: 店铺运营 | D38: 刘灿 | E38: 44383 | F38: 已转正 | G38: 25 | H38: =30-G38 | K38: ='核算明细'!J35 | P38: 15690867521 | Q38: 建设银行 | R38: 刘灿 | S38: 河南省 | T38: 中国建设银行股份有限公司郑州行政区支行 | U38: 6210 8124 3002 9878 390 | V38: 565633890@qq.com
A39: 35 | B39: 抖音组 | C39: 店铺运营 | D39: 晏世兴 | E39: 44848 | F39: 已转正 | G39: 25 | H39: =30-G39 | K39: ='核算明细'!J36 | P39: 13343962791 | Q39: 建设银行 | R39: 晏世兴 | S39: 河南省 | T39: 中国建设银行股份有限公司西平龙泉大道支行 | U39: 6210 8125 7000 4709 811 | V39: 13343962791
A40: 36 | B40: 抖音组 | C40: 主播 | D40: 杜云云 | E40: 44606 | F40: 已转正 | G40: 25 | H40: =30-G40 | K40: ='核算明细'!J37 | P40: 19846794224 | Q40: 工商银行 | R40: 杜云云 | S40: 浙江省 | T40: 工商银行衢州龙游支行 | U40: 6215 5812 0900 2297 275 | V40: dyy19961231@163.com
A41: 37 | B41: 抖音组 | C41: 主播 | D41: 吴利娟 | E41: 44613 | F41: 已转正 | G41: 25 | H41: =30-G41 | K41: ='核算明细'!J38 | P41: 15824377348 | Q41: 农业银行 | R41: 吴利娟 | S41: 浙江省 | T41: 中国农业银行 嘉兴市秀洲区新塍支行 | U41: 6228 4803 4907 4967 374 | V41: 15824377348
A42: 38 | B42: 抖音组 | C42: 助播 | D42: 张颖颖 | E42: 45249 | F42: 已转正 | G42: 25 | H42: =30-G42 | K42: ='核算明细'!J39 | P42: 13174990729 | Q42: 建设银行 | R42: 张颖颖 | S42: 浙江省 | T42: 浦江仙华支行 | U42: 6236 6814 6002 0168 114 | V42: 13174990729
A43: 39 | B43: 抖音组 | C43: 主播 | D43: 吴佩瑶 | E43: 45553 | F43: 已转正 | G43: 25 | H43: =30-G43 | K43: ='核算明细'!J40 | P43: 18458078879 | Q43: 农业银行 | R43: 吴佩瑶 | S43: 浙江省 | T43: 义乌解放支行 | U43: 6230 5203 8000 9337 373 | V43: 18458078879
A44: 40 | B44: 抖音组 | C44: 渠道负责人 | D44: 李井然 | E44: 44573 | F44: 已转正 | G44: 25 | H44: =30-G44 | K44: ='核算明细'!J41 | P44: 18338388571 | Q44: 农业银行 | R44: 李井然 | S44: 河南省 | T44: 中国农业银行唐河县桐寨铺支行 | U44: 6228 4809 7952 2040 679 | V44: 18338388571
A45: 41 | B45: 抖音组 | C45: 主播 | D45: 丁巧 | E45: 45349 | F45: 已转正 | G45: 25 | H45: =30-G45 | K45: ='核算明细'!J42 | P45: 15356953795 | Q45: 工商银行 | R45: 丁巧 | S45: 浙江省 | T45: 义乌商苑支行 | U45: 6212 2612 0801 1433 313 | V45: 15356953795
A46: 42 | B46: 抖音组 | C46: 助播 | D46: 方倩 | E46: 45920 | F46: 已转正 | G46: 25 | H46: =30-G46 | K46: ='核算明细'!J43 | P46: 15267372818 | Q46: 中国银行 | R46: 方倩 | S46: 江西省 | T46: 弋阳支行营业部 | U46: 6216696500004012351 | V46: 15267372818
A47: 43 | B47: 抖音组 | C47: 主播 | D47: 汪铁梅 | E47: 45918 | F47: 已转正 | G47: 25 | H47: =30-G47 | K47: ='核算明细'!J44 | P47: 18257510041 | Q47: 建设银行 | R47: 汪铁梅 | S47: 江西 | T47: 乐平洎阳支行 | U47: 6236682040000827373 | V47: 18257510041
A48: 44 | B48: 抖音组 | C48: 助播 | D48: 黄佳茜 | E48: 45967 | F48: 已转正 | G48: 25 | H48: =30-G48 | K48: ='核算明细'!J45 | P48: 18479316705 | Q48: 工商银行 | R48: 黄佳茜 | S48: 江西省 | T48: 上饶信州支行 | U48: 6222031512000604067 | V48: 18479316705
... A80: 76 | B80: 直播组（联利） | C80: 主播 | D80: 王昌佳 | E80: 46102 | F80: 试用期 | G80: 25 | H80: =30-G80 | K80: ='核算明细'!J77 | P80: 18757441408 | Q80: 工商银行 | R80: 王昌佳 | S80: 浙江省 | T80: 浙江宁波市轻纺城石契街道 | U80: 6222033901013605542 | V80: 18757441408
A81: 77 | B81: 研发中心 | C81: 负责人 | D81: 李潇 | F81: 创始人 | G81: 25 | H81: =30-G81 | K81: ='核算明细'!J78 | P81: 18266908416 | Q81: 兴业银行 | R81: 李潇 | S81: 浙江省 | T81: 兴业银行义乌城中支行 | U81: 622908353248266618
A82: 78 | B82: 研发中心 | C82: 买手 | D82: 叶江华 | E82: 46139 | F82: 试用期 | G82: 25 | H82: =30-G82 | K82: ='核算明细'!J79 | P82: 15083838993 | Q82: 农业银行 | R82: 叶江华 | S82: 广东省 | T82: 中国农业银行深圳八卦岭支行 | U82: 6228 4801 2818 8351 778 | V82: 415790842@qq.com
A83: 79 | B83: 研发中心 | C83: 买手 | D83: 王发莲 | E83: 46139 | F83: 试用期 | G83: 25 | H83: =30-G83 | K83: ='核算明细'!J80 | P83: 15157937580 | Q83: 邮政储蓄银行 | R83: 王发莲 | S83: 浙江省 | T83: 中国邮政储蓄银行义乌市童店营业所 | U83: 6221 5033 8001 3066 299 | V83: 15157937580
A84: 80 | B84: 素材部 | C84: 剪辑 | D84: 纪子怡 | E84: 45181 | F84: 已转正 | G84: 25 | H84: =30-G84 | K84: ='核算明细'!J81 | P84: 13566213260 | Q84: 招商银行 | R84: 纪子怡 | S84: 浙江省 | T84: 温州龙港支行 | U84: 6214 8343 6787 4162 | V84: 13566213260
A85: 81 | B85: 素材部 | C85: 视频号组负责人 | D85: 罗笑笑 | E85: 45014 | F85: 已转正 | G85: 25 | H85: =30-G85 | K85: ='核算明细'!J82 | P85: 17196626654 | Q85: 建设银行 | R85: 罗笑笑 | S85: 安徽省 | T85: 中国建设银行股份有限公司六安叶集 | U85: 6217 0017 8001 6841 884 | V85: 17196626654
A86: 82 | B86: 素材部 | C86: 抖音组负责人 | D86: 曾宇桦 | E86: 45103 | F86: 已转正 | G86: 25 | H86: =30-G86 | K86: ='核算明细'!J83 | P86: 18620739714 | Q86: 工商银行 | R86: 曾宇桦 | S86: 广州省 | T86: 工商银行广州市从化支行 | U86: 6212 2636 0212 7233 831 | V86: 2351736315@qq.com
A87: 83 | B87: 素材部 | C87: 剪辑 | D87: 张豪 | E87: 45353 | F87: 已转正 | G87: 25 | H87: =30-G87 | K87: ='核算明细'!J84 | P87: 15629590927 | Q87: 工商银行 | R87: 张豪 | S87: 湖北省 | T87: 黄石大冶城中支行 | U87: 6215581803005541109 | V87: 178323570@qq.com
A88: 84 | B88: 素材部 | C88: 剪辑 | D88: 郑雪林 | E88: 45182 | F88: 已转正 | G88: 25 | H88: =30-G88 | K88: ='核算明细'!J85 | P88: 18323800209 | Q88: 农商银行 | R88: 郑雪林 | S88: 重庆 | T88: 重庆农商银行 | U88: 6214 6560 1553 3571 | V88: 18323800209
A89: 85 | B89: 素材部 | C89: 剪辑 | D89: 许佳敏 | E89: 45531 | F89: 已转正 | G89: 25 | H89: =30-G89 | K89: ='核算明细'!J86 | P89: 18375369479 | Q89: 招商银行 | R89: 许佳敏 | S89: 浙江省 | T89: 杭州余杭支行 | U89: 6214 8362 1422 4012 | V89: 18375369479
...

Sheet 核算明细
A1: 工号 | B1: 姓名 | C1: 考勤模式 | D1: 应出勤 | E1: 有效打卡天数 | F1: 请假天数 | G1: 加班天数 | H1: 人工天数调整 | I1: 基础实际出勤 | J1: 实际出勤 | K1: 待审核跨日 | L1: 规则说明
A2: 10023 | B2: 陈臣 | C2: standard | D2: 25 | E2: 29 | F2: 0 | G2: 0 | H2: 0 | I2: =IF(OR(C2="exempt",C2="flexible"),D2,E2) | J2: =ROUND(I2+H2,2) | K2: 0 | L2: 标准规则：空白或“-”为休息，有打卡为出勤；疑似跨日未确认前不计入当天
A3: 10183 | B3: 方新阳 | C3: standard | D3: 25 | E3: 27 | F3: 0 | G3: 0 | H3: 0 | I3: =IF(OR(C3="exempt",C3="flexible"),D3,E3) | J3: =ROUND(I3+H3,2) | K3: 0 | L3: 标准规则：空白或“-”为休息，有打卡为出勤；疑似跨日未确认前不计入当天
A4: 10244 | B4: 白雪 | C4: standard | D4: 25 | E4: 10 | F4: 0 | G4: 0 | H4: 0 | I4: =IF(OR(C4="exempt",C4="flexible"),D4,E4) | J4: =ROUND(I4+H4,2) | K4: 0 | L4: 标准规则：空白或“-”为休息，有打卡为出勤；疑似跨日未确认前不计入当天
A5: 10281 | B5: 俞美燕 | C5: standard | D5: 25 | E5: 26 | F5: 0 | G5: 0 | H5: 0 | I5: =IF(OR(C5="exempt",C5="flexible"),D5,E5) | J5: =ROUND(I5+H5,2) | K5: 0 | L5: 标准规则：空白或“-”为休息，有打卡为出勤；疑似跨日未确认前不计入当天
A6: 10055 | B6: 杨国芳 | C6: standard | D6: 25 | E6: 30 | F6: 0 | G6: 0 | H6: 0 | I6: =IF(OR(C6="exempt",C6="flexible"),D6,E6) | J6: =ROUND(I6+H6,2) | K6: 0 | L6: 标准规则：空白或“-”为休息，有打卡为出勤；疑似跨日未确认前不计入当天
A7: 10060 | B7: 李红中 | C7: standard | D7: 25 | E7: 30 | F7: 0 | G7: 0 | H7: 0 | I7: =IF(OR(C7="exempt",C7="flexible"),D7,E7) | J7: =ROUND(I7+H7,2) | K7: 0 | L7: 标准规则：空白或“-”为休息，有打卡为出勤；疑似跨日未确认前不计入当天
A8: 10082 | B8: 李选 | C8: standard | D8: 25 | E8: 28 | F8: 0 | G8: 0 | H8: 0 | I8: =IF(OR(C8="exempt",C8="flexible"),D8,E8) | J8: =ROUND(I8+H8,2) | K8: 0 | L8: 标准规则：空白或“-”为休息，有打卡为出勤；疑似跨日未确认前不计入当天
A9: 10002 | B9: 王娅玲 | C9: standard | D9: 25 | E9: 22 | F9: 0 | G9: 0 | H9: 0 | I9: =IF(OR(C9="exempt",C9="flexible"),D9,E9) | J9: =ROUND(I9+H9,2) | K9: 0 | L9: 标准规则：空白或“-”为休息，有打卡为出勤；疑似跨日未确认前不计入当天
A10: 10039 | B10: 蔡玉婷 | C10: standard | D10: 25 | E10: 12 | F10: 0 | G10: 0 | H10: 0 | I10: =IF(OR(C10="exempt",C10="flexible"),D10,E10) | J10: =ROUND(I10+H10,2) | K10: 0 | L10: 标准规则：空白或“-”为休息，有打卡为出勤；疑似跨日未确认前不计入当天
A11: 10043 | B11: 韩云峰 | C11: standard | D11: 25 | E11: 20 | F11: 0 | G11: 0 | H11: 0 | I11: =IF(OR(C11="exempt",C11="flexible"),D11,E11) | J11: =ROUND(I11+H11,2) | K11: 0 | L11: 标准规则：空白或“-”为休息，有打卡为出勤；疑似跨日未确认前不计入当天
A12: 10125 | B12: 邓帅齐 | C12: standard | D12: 25 | E12: 21 | F12: 0 | G12: 0 | H12: 0 | I12: =IF(OR(C12="exempt",C12="flexible"),D12,E12) | J12: =ROUND(I12+H12,2) | K12: 0 | L12: 标准规则：空白或“-”为休息，有打卡为出勤；疑似跨日未确认前不计入当天
A13: 10150 | B13: 周文博 | C13: standard | D13: 25 | E13: 25 | F13: 0 | G13: 0 | H13: 0 | I13: =IF(OR(C13="exempt",C13="flexible"),D13,E13) | J13: =ROUND(I13+H13,2) | K13: 0 | L13: 标准规则：空白或“-”为休息，有打卡为出勤；疑似跨日未确认前不计入当天
... A130: HR0124 | B130: 沈祥旭 | C130: standard | D130: 25 | E130: 0 | F130: 0 | G130: 0 | H130: 0 | I130: =IF(OR(C130="exempt",C130="flexible"),D130,E130) | J130: =ROUND(I130+H130,2) | K130: 0 | L130: 标准规则：空白或“-”为休息，有打卡为出勤；疑似跨日未确认前不计入当天

Sheet 原始打卡
A1: 姓名 | B1: 组织名称 | C1: 工号 | D1: 考勤规则 | E1: 1 | F1: 2 | G1: 3 | H1: 4 | I1: 5 | J1: 6 | K1: 7 | L1: 8 | M1: 9 | N1: 10 | O1: 11 | P1: 12 | Q1: 13 | R1: 14 | S1: 15 | T1: 16 | U1: 17 | V1: 18 | W1: 19 | X1: 20 | Y1: 21 | Z1: 22 | AA1: 23 | AB1: 24 | AC1: 25 | AD1: 26 | AE1: 27 | AF1: 28 | AG1: 29 | AH1: 30
A2: HikMall_77303323 | B2: 浙江西鸣科技有限公司 | C2: 10001 | D2: 西鸣科技考勤 | E2: - | F2: - | G2: - | H2: - | I2: - | J2: - | K2: - | L2: - | M2: - | N2: - | O2: - | P2: - | Q2: - | R2: - | S2: - | T2: - | U2: - | V2: - | W2: - | X2: - | Y2: - | Z2: - | AA2: - | AB2: - | AC2: - | AD2: - | AE2: - | AF2: - | AG2: - | AH2: -
A3: 李潇 | B3: 研发中心 | C3: 002 | D3: 西鸣科技考勤 | E3: - | F3: - | G3: 20:18 | H3: - | I3: - | J3: - | K3: - | L3: - | M3: 10:39 15:09 | N3: - | O3: - | P3: - | Q3: - | R3: - | S3: - | T3: - | U3: - | V3: - | W3: - | X3: - | Y3: - | Z3: - | AA3: - | AB3: - | AC3: - | AD3: - | AE3: - | AF3: - | AG3: - | AH3: -
A4: 韩启秀 | B4: 供应链 | C4: 4 | D4: 西鸣科技考勤 | E4: - | F4: - | G4: 19:32 | H4: - | I4: - | J4: 16:28 | K4: - | L4: - | M4: - | N4: - | O4: - | P4: - | Q4: 10:09 | R4: - | S4: 09:52 | T4: - | U4: - | V4: - | W4: - | X4: 18:10 | Y4: 17:33 | Z4: - | AA4: - | AB4: - | AC4: 10:59 19:17 | AD4: - | AE4: - | AF4: - | AG4: - | AH4: 10:21
A5: 王娅玲 | B5: 平台系 | C5: 10002 | D5: 西鸣科技考勤 | E5: 09:00 | F5: 08:50 17:21 | G5: 08:59 12:28 | H5: - | I5: - | J5: 09:01 13:31 | K5: - | L5: 19:39 | M5: 08:47 | N5: 08:57 | O5: 09:07 12:09 13:24 22:31 | P5: - | Q5: 08:54 20:11 21:48 | R5: 08:49 | S5: 08:55 20:23 | T5: 08:50 | U5: 16:40 21:09 | V5: - | W5: - | X5: - | Y5: 08:56 | Z5: 08:54 12:08 13:57 14:25 | AA5: 08:56 13:36 | AB5: 08:52 | AC5: 08:57 13:27 18:25 | AD5: - | AE5: 08:54 | AF5: 08:52 | AG5: 08:59 19:32 | AH5: 08:56 11:56
A6: 施丹娜 | B6: 美工部 | C6: 10003 | D6: 西鸣科技考勤 | E6: 09:05 13:15 | F6: 09:02 13:09 18:25 | G6: 09:17 12:56 | H6: - | I6: - | J6: 08:56 17:59 | K6: - | L6: 19:54 | M6: 08:58 10:10 21:05 | N6: 09:27 10:03 | O6: 09:05 12:58 | P6: - | Q6: 09:20 | R6: 09:14 13:03 18:52 | S6: 09:06 10:02 | T6: 12:51 18:19 21:31 | U6: - | V6: 09:10 | W6: - | X6: - | Y6: 09:10 | Z6: 09:06 18:21 | AA6: 09:03 13:47 18:39 | AB6: 09:07 11:43 12:38 | AC6: 09:08 19:56 | AD6: - | AE6: 09:07 14:21 19:07 | AF6: 09:17 12:04 18:18 | AG6: 09:14 18:45 | AH6: 09:13 12:46 18:15
A7: 纪子怡 | B7: 素材部-视频号组 | C7: 10004 | D7: 西鸣科技考勤 | E7: - | F7: - | G7: - | H7: - | I7: - | J7: 08:28 18:32 | K7: 08:28 18:25 | L7: 08:28 18:26 | M7: 08:28 18:14 | N7: 08:26 12:02 18:21 | O7: 08:26 18:22 | P7: - | Q7: 08:29 12:01 18:49 | R7: 08:30 12:04 12:47 18:24 | S7: 08:27 18:24 | T7: 08:30 12:11 18:17 | U7: 08:28 18:42 | V7: 08:29 18:56 | W7: - | X7: 08:25 12:05 18:27 | Y7: 08:29 12:05 18:14 18:17 | Z7: 08:27 18:21 | AA7: 08:29 12:02 18:43 | AB7: 08:27 18:18 | AC7: 08:30 12:04 18:30 | AD7: - | AE7: 08:31 18:18 | AF7: 08:29 12:01 12:02 18:01 | AG7: 08:31 12:03 12:23 18:12 | AH7: 08:32 18:02
A8: 罗笑笑 | B8: 素材部-视频号组 | C8: 10005 | D8: 西鸣科技考勤 | E8: 08:13 12:00 20:21 | F8: 08:18 13:21 14:34 21:01 | G8: 08:09 11:59 19:31 19:33 | H8: - | I8: - | J8: 08:01 13:17 17:57 | K8: - | L8: - | M8: 08:16 09:15 12:04 18:53 | N8: 08:14 11:56 18:23 | O8: 08:23 19:52 | P8: 17:36 | Q8: 08:20 18:39 | R8: 07:34 07:58 | S8: - | T8: 08:23 12:02 21:30 | U8: 08:21 12:02 19:10 | V8: 08:21 19:22 22:21 | W8: - | X8: 08:19 12:29 18:41 | Y8: 08:22 12:10 19:22 | Z8: 08:17 12:21 19:56 | AA8: 08:21 13:27 20:49 | AB8: 08:25 12:01 19:06 | AC8: 08:20 13:29 18:46 | AD8: - | AE8: 08:26 | AF8: 08:18 18:03 19:51 | AG8: 08:29 11:59 18:56 | AH8: -
A9: 曾宇桦 | B9: 素材部-抖音组 | C9: 10006 | D9: 西鸣科技考勤 | E9: 08:37 09:38 12:00 13:31 17:48 18:51 | F9: 08:34 | G9: 08:47 19:46 | H9: - | I9: - | J9: 08:36 | K9: - | L9: 19:08 19:33 | M9: 08:42 13:31 19:38 | N9: 08:34 13:32 20:24 | O9: 08:51 13:31 21:07 | P9: - | Q9: 08:35 20:27 | R9: - | S9: - | T9: 08:39 12:01 13:31 21:31 | U9: 08:41 13:32 19:01 | V9: 08:33 21:41 | W9: - | X9: 08:41 08:50 18:09 | Y9: 08:39 13:32 21:42 | Z9: 08:41 13:32 19:55 | AA9: 08:44 21:48 | AB9: 08:41 19:06 | AC9: 08:40 18:58 | AD9: - | AE9: 08:44 14:32 20:18 | AF9: 08:46 20:11 | AG9: - | AH9: -
A10: 张豪 | B10: 素材部-抖音组 | C10: 10007 | D10: 西鸣科技考勤 | E10: 08:29 18:16 | F10: 08:29 12:00 18:10 | G10: - | H10: - | I10: - | J10: 08:28 18:32 | K10: 08:28 18:25 | L10: 08:28 18:26 | M10: 08:28 18:14 | N10: 08:26 12:01 18:22 | O10: 08:26 18:22 | P10: - | Q10: 08:29 18:24 | R10: 08:30 18:24 | S10: 08:27 12:00 18:22 18:24 | T10: 08:30 18:17 | U10: 08:28 12:01 18:32 | V10: 08:29 18:54 | W10: - | X10: 08:25 12:11 18:25 | Y10: 08:30 12:02 18:14 | Z10: 08:27 12:01 18:20 | AA10: 08:29 12:01 18:43 | AB10: 08:27 12:01 18:18 | AC10: 08:29 12:06 18:30 | AD10: - | AE10: 08:31 18:17 | AF10: 08:29 18:01 | AG10: 08:31 12:04 12:05 18:12 | AH10: 08:32 12:01 18:02
A11: 沈屹铭 | B11: 浙江西鸣科技有限公司 | C11: 10008 | D11: 西鸣科技考勤 | E11: - | F11: - | G11: - | H11: - | I11: - | J11: - | K11: - | L11: 19:24 21:13 次日01:08 | M11: - | N11: - | O11: 20:30 | P11: - | Q11: - | R11: - | S11: - | T11: 17:12 | U11: - | V11: - | W11: - | X11: 19:15 | Y11: 18:48 | Z11: - | AA11: 08:56 18:43 | AB11: - | AC11: 12:44 | AD11: - | AE11: - | AF11: - | AG11: - | AH11: -
A12: 龙云 | B12: 供应链 | C12: 10009 | D12: 西鸣科技考勤 | E12: 08:32 12:15 12:20 13:36 13:40 15:22 23:01 | F12: 08:30 19:10 21:15 | G12: 08:32 12:29 20:51 | H12: - | I12: - | J12: 08:34 11:10 12:06 18:48 21:44 | K12: 08:30 20:24 | L12: 08:30 14:17 21:32 | M12: 08:32 13:35 21:27 | N12: 08:28 12:00 17:10 18:22 21:32 21:34 | O12: 08:33 12:16 22:34 | P12: - | Q12: 08:43 14:34 20:31 22:16 | R12: 08:35 12:01 18:48 20:08 | S12: 08:33 12:06 20:30 | T12: 08:31 12:23 21:40 | U12: 08:32 12:20 13:41 20:57 | V12: 08:35 21:18 | W12: - | X12: 08:33 14:36 18:10 21:33 | Y12: 08:31 12:23 20:14 | Z12: 08:34 12:07 14:14 21:05 | AA12: 08:36 13:39 20:09 | AB12: 08:35 13:41 18:31 20:40 | AC12: 13:33 18:46 | AD12: - | AE12: 08:35 12:09 13:37 20:13 | AF12: 08:34 20:16 | AG12: 08:35 12:10 14:24 20:22 | AH12: 08:32 10:53 19:06
... A174: 周娇 | B174: 供应链 | C174: 10360 | D174: 未加入考勤规则 | E174: - | F174: - | G174: - | H174: - | I174: - | J174: - | K174: - | L174: - | M174: - | N174: - | O174: - | P174: - | Q174: - | R174: - | S174: - | T174: - | U174: - | V174: - | W174: - | X174: - | Y174: - | Z174: - | AA174: - | AB174: - | AC174: - | AD174: - | AE174: - | AF174: - | AG174: - | AH174: -
